#include <iostream>
#include <exception>

using namespace std;

void fun() {}

void test01() {}

int main() {
    test01();
    return 0;
}